Workbook

Sheet Instructions
B2: PHOENIX PRECAST / PHOENIX CONSTRUCTION BV
B3: MONTHLY LABOR COST & OVERTIME CONTROL TRACKER
B4: Cross-Border Operations: Sint Maarten (Dutch side) & Saint Martin (French side) | Precast Factory + Erection | Grok Accountant Assistant | July 2026 | Confidential - Management Use Only
B6: HOW TO USE - EASY MONTHLY PROCESS
B7: 1. At month-end, collect ALL payslips from both entities (French Saint Martin CDI/mutuelle payslips + Dutch Sint Maarten payslips).
B8: 2. EASIEST OPTION (recommended): Send me the PDF payslips (or a zip/folder) via email or upload here. I extract employee name, entity, regular hours, OT hours (25%/50% or equivalent), gross pay, employer social charges (if shown on bulletin de paie), and populate the Labor_Data_Entry sheet accurately. This respects French detailed cotisations and Dutch formats.
B9: 3. SELF-SERVICE OPTION: Open Labor_Data_Entry sheet and enter data manually from each payslip. Use dropdowns for Entity and Department. Yellow cells are inputs.
B10: 4. On the Dashboard sheet: Update the YELLOW 'Report Month' cell (e.g. 2026-07). Enter your monthly Turnover figure (from QuickBooks, in EUR or local + rate). Update XCG to EUR exchange rate if needed (current peg ~1 XCG ≈ 0.56 EUR; confirm with your bank).
B11: 5. Review KPIs instantly: Total employer labor cost, total OT hours worked, OT as % of hours, Labor Cost as % of Turnover, breakdown by French vs Dutch entity, and employee-level OT detail. Compare to prior months and your targets.
B12: 6. I will also provide a short narrative analysis each month (trends, red flags on excessive OT, margin impact, hiring vs OT recommendation, compliance notes). Archive payslips + this report together for your records (audit trail for labor inspections, tax, or disputes).
B14: WHY THIS MATTERS FOR YOUR BUSINESS (Precast + Erection Expansion)
B15: • True cost visibility: French side employer charges often add 40-50%+ on gross (URSSAF/CGSS, retraite, chômage, mutuelle, prévoyance, etc.). Dutch side lower but still material. This tracker shows full employer cost, not just net or gross.
... B61: • Send next payslips (any month) + turnover figures. Tracker will grow with full history and department-level insights.

Sheet Labor_Data_Entry
A1: LABOR DATA ENTRY - Source: Payslips (French bulletins de paie & Dutch payslips) | Add new rows each month | Yellow = Input | Green = Formula
A3: Month (YYYY-MM) | B3: Employee Name | C3: Entity | D3: Department | E3: Regular Hours | F3: OT Hours @25% | G3: OT Hours @50% | H3: Gross Pay (Local) | I3: Employer Charges (Local) | J3: Total Cost (Local) | K3: Currency | L3: Total Cost (EUR) | M3: Notes / Project | N3: Total Cost (USD) | O3: Production_Only (Yes/No)
A4: 2025-10 | B4: Steven Bryan | C4: Dutch - Sint Maarten | D4: Support | E4: 158.95 | F4: 0 | G4: 9.87 | H4: 4253.07 | I4: 795.25 | J4: =H4+I4 -> 5048.32 | K4: XCG | L4: =IF(K4="XCG",J4*Dashboard!$B$46,IF(K4="EUR",J4*Dashboard!$B$47,"")) -> 2816.9626 | M4: Q4 2025 Dutch staff - Oct payslip; OT incl. 150% + Saturday premium | N4: =IF(K4="XCG",J4*Dashboard!$B$46,IF(K4="EUR",J4*Dashboard!$B$47,"")) -> 2816.9626 | O4: Yes
A5: 2025-10 | B5: Steve Donovan Gordon | C5: Dutch - Sint Maarten | D5: Slab/Wall production | E5: 174 | F5: 0 | G5: 29.5 | H5: 6891.78 | I5: 1055.1 | J5: =H5+I5 -> 7946.88 | K5: XCG | L5: =IF(K5="XCG",J5*Dashboard!$B$46,IF(K5="EUR",J5*Dashboard!$B$47,"")) -> 4434.359 | M5: Q4 2025 Dutch staff - Oct; high OT ~17% of hours + allowances (garbage/gas) | N5: =IF(K5="XCG",J5*Dashboard!$B$46,IF(K5="EUR",J5*Dashboard!$B$47,"")) -> 4434.359 | O5: Yes
A6: 2025-10 | B6: Calvin Groeneveldt | C6: Dutch - Sint Maarten | D6: Slab/Wall production | E6: 175.23 | F6: 0 | G6: 24.92 | H6: 6360.82 | I6: 901.16 | J6: =H6+I6 -> 7261.98 | K6: XCG | L6: =IF(K6="XCG",J6*Dashboard!$B$46,IF(K6="EUR",J6*Dashboard!$B$47,"")) -> 4052.1848 | M6: Q4 2025 Dutch staff - Oct; OT incl. Saturday work | N6: =IF(K6="XCG",J6*Dashboard!$B$46,IF(K6="EUR",J6*Dashboard!$B$47,"")) -> 4052.1848 | O6: Yes
A7: 2025-10 | B7: Paul Anthony Harrison | C7: Dutch - Sint Maarten | D7: Beam/Stairs Rebar | E7: 176.92 | F7: 0 | G7: 20.93 | H7: 5039.5 | I7: 557.83 | J7: =H7+I7 -> 5597.33 | K7: XCG | L7: =IF(K7="XCG",J7*Dashboard!$B$46,IF(K7="EUR",J7*Dashboard!$B$47,"")) -> 3123.3101 | M7: Q4 2025 Dutch staff - Oct; hourly 27.00 + seniority; no AOV addition listed this month | N7: =IF(K7="XCG",J7*Dashboard!$B$46,IF(K7="EUR",J7*Dashboard!$B$47,"")) -> 3123.3101 | O7: Yes
A8: 2025-11 | B8: Steven Bryan | C8: Dutch - Sint Maarten | D8: Support | E8: 137.33 | F8: 0 | G8: 7.35 | H8: 3658.1 | I8: 747.68 | J8: =H8+I8 -> 4405.78 | K8: XCG | L8: =IF(K8="XCG",J8*Dashboard!$B$46,IF(K8="EUR",J8*Dashboard!$B$47,"")) -> 2458.4252 | M8: Q4 2025 Dutch staff - Nov; advance payment deducted; Saturday work included in OT hrs | N8: =IF(K8="XCG",J8*Dashboard!$B$46,IF(K8="EUR",J8*Dashboard!$B$47,"")) -> 2458.4252 | O8: Yes
A9: 2025-11 | B9: Steve Donovan Gordon | C9: Dutch - Sint Maarten | D9: Slab/Wall production | E9: 149.83 | F9: 0 | G9: 22.5 | H9: 6127.46 | I9: 940.64 | J9: =H9+I9 -> 7068.1 | K9: XCG | L9: =IF(K9="XCG",J9*Dashboard!$B$46,IF(K9="EUR",J9*Dashboard!$B$47,"")) -> 3943.9998 | M9: Q4 2025 Dutch staff - Nov; loan repayment + advance; high OT | N9: =IF(K9="XCG",J9*Dashboard!$B$46,IF(K9="EUR",J9*Dashboard!$B$47,"")) -> 3943.9998 | O9: Yes
A10: 2025-11 | B10: Calvin Groeneveldt | C10: Dutch - Sint Maarten | D10: Slab/Wall production | E10: 152.13 | F10: 0 | G10: 10.65 | H10: 4281.16 | I10: 814.78 | J10: =H10+I10 -> 5095.94 | K10: XCG | L10: =IF(K10="XCG",J10*Dashboard!$B$46,IF(K10="EUR",J10*Dashboard!$B$47,"")) -> 2843.5345 | M10: Q4 2025 Dutch staff - Nov; advance payment; OT mainly 150% | N10: =IF(K10="XCG",J10*Dashboard!$B$46,IF(K10="EUR",J10*Dashboard!$B$47,"")) -> 2843.5345 | O10: Yes
A11: 2025-11 | B11: Paul Anthony Harrison | C11: Dutch - Sint Maarten | D11: Beam/Stairs Rebar | E11: 152 | F11: 0 | G11: 16.9 | H11: 5307.8 | I11: 790.58 | J11: =H11+I11 -> 6098.38 | K11: XCG | L11: =IF(K11="XCG",J11*Dashboard!$B$46,IF(K11="EUR",J11*Dashboard!$B$47,"")) -> 3402.896 | M11: Q4 2025 Dutch staff - Nov; advance + loan elements; consistent OT | N11: =IF(K11="XCG",J11*Dashboard!$B$46,IF(K11="EUR",J11*Dashboard!$B$47,"")) -> 3402.896 | O11: Yes
A12: 2025-12 | B12: Steven Bryan | C12: Dutch - Sint Maarten | D12: Support | E12: 105.63 | F12: 0 | G12: 0.87 | H12: 3812.68 | I12: 759.02 | J12: =H12+I12 -> 4571.7 | K12: XCG | L12: =IF(K12="XCG",J12*Dashboard!$B$46,IF(K12="EUR",J12*Dashboard!$B$47,"")) -> 2551.0086 | M12: Q4 2025 Dutch staff - Dec; vacation payout + holiday; lower regular hours this month; low OT | N12: =IF(K12="XCG",J12*Dashboard!$B$46,IF(K12="EUR",J12*Dashboard!$B$47,"")) -> 2551.0086 | O12: Yes
A13: 2025-12 | B13: Steve Donovan Gordon | C13: Dutch - Sint Maarten | D13: Slab/Wall production | E13: 115.7 | F13: 0 | G13: 9.48 | H13: 5316.12 | I13: 943.44 | J13: =H13+I13 -> 6259.56 | K13: XCG | L13: =IF(K13="XCG",J13*Dashboard!$B$46,IF(K13="EUR",J13*Dashboard!$B$47,"")) -> 3492.8345 | M13: Q4 2025 Dutch staff - Dec; vacation payout + holiday + garbage/gas; moderate OT | N13: =IF(K13="XCG",J13*Dashboard!$B$46,IF(K13="EUR",J13*Dashboard!$B$47,"")) -> 3492.8345 | O13: Yes
A14: 2025-12 | B14: Calvin Groeneveldt | C14: Dutch - Sint Maarten | D14: Slab/Wall production | E14: 119 | F14: 0 | G14: 5.97 | H14: 4664.51 | I14: 845.78 | J14: =H14+I14 -> 5510.29 | K14: XCG | L14: =IF(K14="XCG",J14*Dashboard!$B$46,IF(K14="EUR",J14*Dashboard!$B$47,"")) -> 3074.7418 | M14: Q4 2025 Dutch staff - Dec; vacation payout + holiday; moderate OT | N14: =IF(K14="XCG",J14*Dashboard!$B$46,IF(K14="EUR",J14*Dashboard!$B$47,"")) -> 3074.7418 | O14: Yes
A15: 2025-12 | B15: Paul Anthony Harrison | C15: Dutch - Sint Maarten | D15: Beam/Stairs Rebar | E15: 113.28 | F15: 0 | G15: 11.9 | H15: 4657.34 | I15: 791.99 | J15: =H15+I15 -> 5449.33 | K15: XCG | L15: =IF(K15="XCG",J15*Dashboard!$B$46,IF(K15="EUR",J15*Dashboard!$B$47,"")) -> 3040.7261 | M15: Q4 2025 Dutch staff - Dec; vacation payout + holiday; OT present | N15: =IF(K15="XCG",J15*Dashboard!$B$46,IF(K15="EUR",J15*Dashboard!$B$47,"")) -> 3040.7261 | O15: Yes
... A36: 2025-12 | B36: Sobalvarro Garcia Profirio Alberto | C36: French - Saint Martin | D36: Slab/Wall Rebar | E36: 96.52 | F36: 0 | G36: 0 | H36: 1336.39 | I36: 345.19 | J36: =H36+I36 -> 1681.58 | K36: EUR | L36: =IF(K36="XCG",J36*Dashboard!$B$46,IF(K36="EUR",J36*Dashboard!$B$47,"")) -> 1917.0012 | M36: Dec 2025 French production; absences 55.15h + Abs 20/12-31/12; TOTAL VERSE 1,681.58 | N36: =IF(K36="XCG",J36*Dashboard!$B$46,IF(K36="EUR",J36*Dashboard!$B$47,"")) -> 1917.0012 | O36: Yes
A37: 2026-01 | B37: Morris Fernando Ovando | C37: French - Saint Martin | D37: Slab/Wall Rebar | E37: 0 | F37: 0 | G37: 0 | H37: 2095.35 | I37: 729.5 | J37: =H37+I37 -> 2824.85 | K37: EUR | L37: =IF(K37="XCG",J37*Dashboard!$B$46,IF(K37="EUR",J37*Dashboard!$B$47,"")) -> 3220.329 | M37: End of contract 05/01/2026 - Indemnité précarité 2,095.35 (no hours). Cost included in avg rate as requested. Flag for visibility. | O37: Yes
A38: 2026-01 | B38: Delaney Francis Theodore | C38: French - Saint Martin | D38: Beam/Stairs production | E38: 190.2 | F38: 23.53 | G38: 15 | H38: 3053.74 | I38: 800 | J38: =H38+I38 -> 3853.74 | K38: EUR | L38: =IF(K38="XCG",J38*Dashboard!$B$46,IF(K38="EUR",J38*Dashboard!$B$47,"")) -> 4393.2636 | M38: Jan 2026 French production; OT 25% 23.53h + 50% 15h; high brut. | O38: Yes
A39: 2026-01 | B39: Cesar Kenny | C39: French - Saint Martin | D39: Crane operator | E39: 184.67 | F39: 22.75 | G39: 10.25 | H39: 2736.76 | I39: 761.86 | J39: =H39+I39 -> 3498.62 | K39: EUR | L39: =IF(K39="XCG",J39*Dashboard!$B$46,IF(K39="EUR",J39*Dashboard!$B$47,"")) -> 3988.4268 | M39: Jan 2026 French production; OT 25% 22.75h + 50% 10.25h. | O39: Yes
A40: 2026-01 | B40: Pochette Elie | C40: French - Saint Martin | D40: Slab/Wall production | E40: 133.52 | F40: 0 | G40: 0 | H40: 1759.22 | I40: 450.87 | J40: =H40+I40 -> 2210.09 | K40: EUR | L40: =IF(K40="XCG",J40*Dashboard!$B$46,IF(K40="EUR",J40*Dashboard!$B$47,"")) -> 2519.5026 | M40: Jan 2026 French (from pattern); check full for exact OT/absences. | O40: Yes
A41: 2026-01 | B41: Richemon Jeytro | C41: French - Saint Martin | D41: Beam/Stairs production | E41: 145.48 | F41: 5.43 | G41: 0 | H41: 1745.43 | I41: 460.3 | J41: =H41+I41 -> 2205.73 | K41: EUR | L41: =IF(K41="XCG",J41*Dashboard!$B$46,IF(K41="EUR",J41*Dashboard!$B$47,"")) -> 2514.5322 | M41: Jan 2026 French (from pattern). | O41: Yes
A42: 2026-01 | B42: Gumbs Chrisphin | C42: French - Saint Martin | D42: Support | E42: 137.42 | F42: 13.5 | G42: 0 | H42: 1672.6 | I42: 408.41 | J42: =H42+I42 -> 2081.01 | K42: EUR | L42: =IF(K42="XCG",J42*Dashboard!$B$46,IF(K42="EUR",J42*Dashboard!$B$47,"")) -> 2372.3514 | M42: Jan 2026 French (from pattern). | O42: Yes
A43: 2026-01 | B43: Sobalvarro Garcia Profirio Alberto | C43: French - Saint Martin | D43: Slab/Wall Rebar | E43: 218.67 | F43: 38.25 | G43: 28.75 | H43: 3359.1 | I43: 803.52 | J43: =H43+I43 -> 4162.62 | K43: EUR | L43: =IF(K43="XCG",J43*Dashboard!$B$46,IF(K43="EUR",J43*Dashboard!$B$47,"")) -> 4745.3868 | M43: Jan 2026 French (from pattern; high OT). | O43: Yes
A44: 2026-02 | B44: Delaney Francis Theodore | C44: French - Saint Martin | D44: Beam/Stairs production | E44: 144.41 | F44: 14.9 | G44: 0 | H44: 2222.03 | I44: 608.61 | J44: =H44+I44 -> 2830.64 | K44: EUR | L44: =IF(K44="XCG",J44*Dashboard!$B$46,IF(K44="EUR",J44*Dashboard!$B$47,"")) -> 3226.9296 | M44: Feb 2026 French; OT 25% 14.9h; absences + regul trop perçu Jan. | O44: Yes
A45: 2026-02 | B45: Cesar Kenny | C45: French - Saint Martin | D45: Crane operator | E45: 163.44 | F45: 21.15 | G45: 5.2 | H45: 2398.59 | I45: 699.93 | J45: =H45+I45 -> 3098.52 | K45: EUR | L45: =IF(K45="XCG",J45*Dashboard!$B$46,IF(K45="EUR",J45*Dashboard!$B$47,"")) -> 3532.3128 | M45: Feb 2026 French; OT 25% 21.15h + 50% 5.2h; absences + regul. | O45: Yes
A46: 2026-02 | B46: Pochette Elie | C46: French - Saint Martin | D46: Slab/Wall production | E46: 146.75 | F46: 17.25 | G46: 0 | H46: 1815.77 | I46: 482.93 | J46: =H46+I46 -> 2298.7 | K46: EUR | L46: =IF(K46="XCG",J46*Dashboard!$B$46,IF(K46="EUR",J46*Dashboard!$B$47,"")) -> 2620.518 | M46: Feb 2026 French; OT 25% 17.25h; absences + regul + défiscalisation. | O46: Yes
A47: 2026-03 | B47: Delaney Francis Theodore | C47: French - Saint Martin | D47: Beam/Stairs production | E47: 170.47 | F47: 18.8 | G47: 0 | H47: 2627.55 | I47: 832.39 | J47: =H47+I47 -> 3459.94 | K47: EUR | L47: =IF(K47="XCG",J47*Dashboard!$B$46,IF(K47="EUR",J47*Dashboard!$B$47,"")) -> 3944.3316 | M47: Mar 2026 French; OT 25% 18.8h. | O47: Yes
A48: 2026-03 | B48: Cesar Kenny | C48: French - Saint Martin | D48: Crane operator | E48: 170.57 | F48: 18.9 | G48: 0 | H48: 2454.13 | I48: 808.11 | J48: =H48+I48 -> 3262.24 | K48: EUR | L48: =IF(K48="XCG",J48*Dashboard!$B$46,IF(K48="EUR",J48*Dashboard!$B$47,"")) -> 3718.9536 | M48: Mar 2026 French; OT 25% 18.9h. | O48: Yes
... A62: 2026-03 | B62: Calvin Groeneveldt | C62: Dutch - Sint Maarten | D62: Slab/Wall production | E62: 173.92 | F62: 2.63 | G62: 0 | H62: 5140.51 | I62: 3510.71 | J62: =H62+I62 -> 8651.22 | K62: XCG | L62: =IF(K62="XCG",J62*Dashboard!$B$46,IF(K62="EUR",J62*Dashboard!$B$47,"")) -> 4827.3808 | M62: Mar 2026 Dutch; OT 150% 2.63h; advances. | O62: Yes

Sheet Dashboard
A1: DASHBOARD - MONTHLY LABOR COST & OVERTIME OVERVIEW | Phoenix Precast & Construction (Sint Maarten / Saint Martin)
A3: REPORT PARAMETERS (Yellow cells = update each month)
A4: Report Month (YYYY-MM): | B4: 2026-06
A5: Monthly Turnover (EUR): | B5: 185000
A6: XCG to EUR Exchange Rate: | B6: 0.56 | C6: (Confirm with bank; 1 XCG ≈ 0.56 EUR typical)
A10: XCG_to_EUR_Rate (for formulas): | B10: 0.56
A12: KEY PERFORMANCE INDICATORS - Selected Month
A14: Total Regular Hours: | B14: =SUMIF(Labor_Data_Entry!A:A,$B$4,Labor_Data_Entry!E:E) -> 0 | C14: Total OT Hours (all): | D14: =SUMIF(Labor_Data_Entry!A:A,$B$4,Labor_Data_Entry!F:F)+SUMIF(Labor_Data_Entry!A:A,$B$4,Labor_Data_Entry!G:G) -> 0
A15: Total OT Hours @25%: | B15: =SUMIF(Labor_Data_Entry!A:A,$B$4,Labor_Data_Entry!F:F) -> 0 | C15: Total OT Hours @50%: | D15: =SUMIF(Labor_Data_Entry!A:A,$B$4,Labor_Data_Entry!G:G) -> 0
A16: Total Employer Labor Cost (EUR): | B16: =SUMIF(Labor_Data_Entry!A:A,$B$4,Labor_Data_Entry!L:L) -> 0 | C16: Labor Cost as % of Turnover: | D16: =IFERROR(B16/B5,0) -> 0
A17: Total Employees Paid (this month): | B17: =COUNTIF(Labor_Data_Entry!A:A,$B$4) -> 0 | C17: OT Hours as % of Total Hours: | D17: =IFERROR(D14/(B14+D14),0) -> 0
A18: Avg Employer Cost per Hour (EUR): | B18: =IFERROR(B16/(B14+D14),0) -> 0
A20: BREAKDOWN BY ENTITY (Selected Month)
A21: Entity | B21: Regular Hrs | C21: OT Hrs | D21: Total Cost (EUR) | E21: % of Total Cost
A22: French - Saint Martin | B22: =SUMIFS(Labor_Data_Entry!E:E,Labor_Data_Entry!A:A,$B$4,Labor_Data_Entry!C:C,"French - Saint Martin") -> 0 | C22: =SUMIFS(Labor_Data_Entry!F:F,Labor_Data_Entry!A:A,$B$4,Labor_Data_Entry!C:C,"French - Saint Martin")+SUMIFS(Labor_Data_Entry!G:G,Labor_Data_Entry!A:A,$B$4,Labor_Data_Entry!C:C,"French - Saint Martin") -> 0 | D22: =SUMIFS(Labor_Data_Entry!L:L,Labor_Data_Entry!A:A,$B$4,Labor_Data_Entry!C:C,"French - Saint Martin") -> 0 | E22: =IFERROR(D22/$B$16,0) -> 0
A23: Dutch - Sint Maarten | B23: =SUMIFS(Labor_Data_Entry!E:E,Labor_Data_Entry!A:A,$B$4,Labor_Data_Entry!C:C,"Dutch - Sint Maarten") -> 0 | C23: =SUMIFS(Labor_Data_Entry!F:F,Labor_Data_Entry!A:A,$B$4,Labor_Data_Entry!C:C,"Dutch - Sint Maarten")+SUMIFS(Labor_Data_Entry!G:G,Labor_Data_Entry!A:A,$B$4,Labor_Data_Entry!C:C,"Dutch - Sint Maarten") -> 0 | D23: =SUMIFS(Labor_Data_Entry!L:L,Labor_Data_Entry!A:A,$B$4,Labor_Data_Entry!C:C,"Dutch - Sint Maarten") -> 0 | E23: =IFERROR(D23/$B$16,0) -> 0
A25: OVERTIME DETAIL - Employees with OT in Selected Month (sorted by OT descending in full data)
A26: Employee | B26: Entity | C26: OT Hours | D26: Regular Hours | E26: OT % of His/Her Hours | F26: Notes
A27: OVERTIME DETAIL - Employees with OT in Selected Month (French + Dutch sides)
A28: Employee | B28: Entity / Side | C28: OT Hours | D28: Regular Hours | E28: OT % of Their Hours | F28: Notes
A29: (Dynamic list populates from main data when filtered by month. Example below based on Q4 patterns; full list appears as data grows.)
A30: Cesar Kenny (example) | B30: French - Saint Martin (Crane) | C30: 0 | D30: 151.67 | E30: 0 | F30: Often low OT as crane role
A31: Richemon Jeytro (example) | B31: French - Saint Martin (Beam/Stairs) | C31: 5.93 | D31: 136.6 | E31: 0.042 | F31: Typical production OT
A32: Steve Donovan Gordon (example) | B32: Dutch - Sint Maarten (Slab/Wall) | C32: 9.48 | D32: 115.7 | E32: 0.076 | F32: Higher OT in some months
A33: Paul Anthony Harrison (example) | B33: Dutch - Sint Maarten (Beam/Stairs Rebar) | C33: 11.9 | D33: 113.28 | E33: 0.095 | F33: Consistent rebar OT
A35: To see full live OT list for any month: Filter Labor_Data_Entry by Month and sort by OT columns, or I can add a dedicated dynamic OT report tab.
A36: From sample data (May vs June): OT hours increased significantly in June (esp. French erection & factory). Labor cost rose accordingly. Labor/turnover ratio needs your real turnover input to assess if still healthy (target typically 28-35% for precast depending on mix).
A40: This dashboard + underlying data is prepared specifically for your cross-border precast operations. It gives you the visibility to control labor costs, manage OT proactively, and make informed decisions on staffing for your growth to $3M+ revenue. Send payslips anytime for update.
A45: EXCHANGE RATES FOR USD CONSOLIDATION (update monthly)
A46: XCG to USD Rate (peg ~1 XCG = 0.558 USD): | B46: 0.558
A47: EUR to USD Rate (approx; update per month or use average): | B47: 1.14
A48: Note: Dutch base is XCG (paid partly in USD). French is EUR. Use these rates for consolidated USD view below.
A50: SELECTED MONTH - USD VIEW & AVERAGE HOURLY COST
A52: Total Employer Labor Cost (USD): | B52: =SUMIF(Labor_Data_Entry!A:A,$B$4,Labor_Data_Entry!N:N) -> 0
A53: Total Hours (Regular + OT): | B53: =SUMIF(Labor_Data_Entry!A:A,$B$4,Labor_Data_Entry!E:E)+SUMIF(Labor_Data_Entry!A:A,$B$4,Labor_Data_Entry!F:F)+SUMIF(Labor_Data_Entry!A:A,$B$4,Labor_Data_Entry!G:G) -> 0
A54: Average Hourly Labor Cost (USD): | B54: =IFERROR(B52/B53,0) -> 0
A56: Breakdown by Side (USD) - French vs Dutch for selected month
A57: French - Saint Martin (USD): | B57: =SUMIFS(Labor_Data_Entry!N:N,Labor_Data_Entry!A:A,$B$4,Labor_Data_Entry!C:C,"French - Saint Martin") -> 0
A58: Dutch - Sint Maarten (USD): | B58: =SUMIFS(Labor_Data_Entry!N:N,Labor_Data_Entry!A:A,$B$4,Labor_Data_Entry!C:C,"Dutch - Sint Maarten") -> 0
A60: CHARTS & VISUALS: See pie chart above for side split. Open in Excel for interactive filtering, pivot tables by Department (use the Department column), or add more charts (e.g., OT by Dept, Monthly Trend). I can add specific charts on request (e.g., Avg Hourly Trend line, Cost by exact Department).
...

Sheet 12_Month_Trends
A1: 12-MONTH TRENDS DASHBOARD - PRODUCTION STAFF ONLY (Excludes Management & User)
A2: All metrics below use ONLY rows marked 'Yes' in Production_Only column. Management (Sjors, Niels, Rick) excluded. This gives clean view of actual factory labor cost efficiency.
A4: MONTHLY PRODUCTION LABOR COST COMPARISON (French vs Dutch) - Avg Hourly USD
A5: Month | B5: French Hours | C5: French Total Cost USD | D5: French Avg $/hr | E5: Dutch Hours | F5: Dutch Total Cost USD | G5: Dutch Avg $/hr | H5: Combined Hours | I5: Combined Cost USD | J5: Combined Avg $/hr | K5: Key Insight
A6: 2025-10 | B6: =SUMIFS(Labor_Data_Entry!E:E,Labor_Data_Entry!A:A,A6,Labor_Data_Entry!C:C,"French - Saint Martin",Labor_Data_Entry!O:O,"Yes") + SUMIFS(Labor_Data_Entry!F:F,Labor_Data_Entry!A:A,A6,Labor_Data_Entry!C:C,"French - Saint Martin",Labor_Data_Entry!O:O,"Yes") + SUMIFS(Labor_Data_Entry!G:G,Labor_Data_Entry!A:A,A6,Labor_Data_Entry!C:C,"French - Saint Martin",Labor_Data_Entry!O:O,"Yes") -> 1108.09 | C6: =SUMIFS(Labor_Data_Entry!N:N,Labor_Data_Entry!A:A,A6,Labor_Data_Entry!C:C,"French - Saint Martin",Labor_Data_Entry!O:O,"Yes") -> 20691.559 | D6: =IFERROR(C6/B6,0) -> 18.673175 | E6: =SUMIFS(Labor_Data_Entry!E:E,Labor_Data_Entry!A:A,A6,Labor_Data_Entry!C:C,"Dutch - Sint Maarten",Labor_Data_Entry!O:O,"Yes") + SUMIFS(Labor_Data_Entry!F:F,Labor_Data_Entry!A:A,A6,Labor_Data_Entry!C:C,"Dutch - Sint Maarten",Labor_Data_Entry!O:O,"Yes") + SUMIFS(Labor_Data_Entry!G:G,Labor_Data_Entry!A:A,A6,Labor_Data_Entry!C:C,"Dutch - Sint Maarten",Labor_Data_Entry!O:O,"Yes") -> 770.32 | F6: =SUMIFS(Labor_Data_Entry!N:N,Labor_Data_Entry!A:A,A6,Labor_Data_Entry!C:C,"Dutch - Sint Maarten",Labor_Data_Entry!O:O,"Yes") -> 14426.817 | G6: =IFERROR(F6/E6,0) -> 18.728342 | H6: =B6+E6 -> 1878.41 | I6: =C6+F6 -> 35118.375 | J6: =IFERROR(I6/H6,0) -> 18.695799 | K6: French cheaper per hour; good volume
A7: 2025-11 | B7: =SUMIFS(Labor_Data_Entry!E:E,Labor_Data_Entry!A:A,A7,Labor_Data_Entry!C:C,"French - Saint Martin",Labor_Data_Entry!O:O,"Yes") + SUMIFS(Labor_Data_Entry!F:F,Labor_Data_Entry!A:A,A7,Labor_Data_Entry!C:C,"French - Saint Martin",Labor_Data_Entry!O:O,"Yes") + SUMIFS(Labor_Data_Entry!G:G,Labor_Data_Entry!A:A,A7,Labor_Data_Entry!C:C,"French - Saint Martin",Labor_Data_Entry!O:O,"Yes") -> 1003.55 | C7: =SUMIFS(Labor_Data_Entry!N:N,Labor_Data_Entry!A:A,A7,Labor_Data_Entry!C:C,"French - Saint Martin",Labor_Data_Entry!O:O,"Yes") -> 23637.501 | D7: =IFERROR(C7/B7,0) -> 23.553885 | E7: =SUMIFS(Labor_Data_Entry!E:E,Labor_Data_Entry!A:A,A7,Labor_Data_Entry!C:C,"Dutch - Sint Maarten",Labor_Data_Entry!O:O,"Yes") + SUMIFS(Labor_Data_Entry!F:F,Labor_Data_Entry!A:A,A7,Labor_Data_Entry!C:C,"Dutch - Sint Maarten",Labor_Data_Entry!O:O,"Yes") + SUMIFS(Labor_Data_Entry!G:G,Labor_Data_Entry!A:A,A7,Labor_Data_Entry!C:C,"Dutch - Sint Maarten",Labor_Data_Entry!O:O,"Yes") -> 648.69 | F7: =SUMIFS(Labor_Data_Entry!N:N,Labor_Data_Entry!A:A,A7,Labor_Data_Entry!C:C,"Dutch - Sint Maarten",Labor_Data_Entry!O:O,"Yes") -> 12648.856 | G7: =IFERROR(F7/E7,0) -> 19.499076 | H7: =B7+E7 -> 1652.24 | I7: =C7+F7 -> 36286.357 | J7: =IFERROR(I7/H7,0) -> 21.961916 | K7: French slightly higher cost
A8: 2025-12 | B8: =SUMIFS(Labor_Data_Entry!E:E,Labor_Data_Entry!A:A,A8,Labor_Data_Entry!C:C,"French - Saint Martin",Labor_Data_Entry!O:O,"Yes") + SUMIFS(Labor_Data_Entry!F:F,Labor_Data_Entry!A:A,A8,Labor_Data_Entry!C:C,"French - Saint Martin",Labor_Data_Entry!O:O,"Yes") + SUMIFS(Labor_Data_Entry!G:G,Labor_Data_Entry!A:A,A8,Labor_Data_Entry!C:C,"French - Saint Martin",Labor_Data_Entry!O:O,"Yes") -> 695.64 | C8: =SUMIFS(Labor_Data_Entry!N:N,Labor_Data_Entry!A:A,A8,Labor_Data_Entry!C:C,"French - Saint Martin",Labor_Data_Entry!O:O,"Yes") -> 14832.05 | D8: =IFERROR(C8/B8,0) -> 21.321445 | E8: =SUMIFS(Labor_Data_Entry!E:E,Labor_Data_Entry!A:A,A8,Labor_Data_Entry!C:C,"Dutch - Sint Maarten",Labor_Data_Entry!O:O,"Yes") + SUMIFS(Labor_Data_Entry!F:F,Labor_Data_Entry!A:A,A8,Labor_Data_Entry!C:C,"Dutch - Sint Maarten",Labor_Data_Entry!O:O,"Yes") + SUMIFS(Labor_Data_Entry!G:G,Labor_Data_Entry!A:A,A8,Labor_Data_Entry!C:C,"Dutch - Sint Maarten",Labor_Data_Entry!O:O,"Yes") -> 481.83 | F8: =SUMIFS(Labor_Data_Entry!N:N,Labor_Data_Entry!A:A,A8,Labor_Data_Entry!C:C,"Dutch - Sint Maarten",Labor_Data_Entry!O:O,"Yes") -> 12159.311 | G8: =IFERROR(F8/E8,0) -> 25.235687 | H8: =B8+E8 -> 1177.47 | I8: =C8+F8 -> 26991.361 | J8: =IFERROR(I8/H8,0) -> 22.923183 | K8: Dutch spikes (vacation payouts + lower hours)
A9: 2026-01 | B9: =SUMIFS(Labor_Data_Entry!E:E,Labor_Data_Entry!A:A,A9,Labor_Data_Entry!C:C,"French - Saint Martin",Labor_Data_Entry!O:O,"Yes") + SUMIFS(Labor_Data_Entry!F:F,Labor_Data_Entry!A:A,A9,Labor_Data_Entry!C:C,"French - Saint Martin",Labor_Data_Entry!O:O,"Yes") + SUMIFS(Labor_Data_Entry!G:G,Labor_Data_Entry!A:A,A9,Labor_Data_Entry!C:C,"French - Saint Martin",Labor_Data_Entry!O:O,"Yes") -> 1167.42 | C9: =SUMIFS(Labor_Data_Entry!N:N,Labor_Data_Entry!A:A,A9,Labor_Data_Entry!C:C,"French - Saint Martin",Labor_Data_Entry!O:O,"Yes") -> 0 | D9: =IFERROR(C9/B9,0) -> 0 | E9: =SUMIFS(Labor_Data_Entry!E:E,Labor_Data_Entry!A:A,A9,Labor_Data_Entry!C:C,"Dutch - Sint Maarten",Labor_Data_Entry!O:O,"Yes") + SUMIFS(Labor_Data_Entry!F:F,Labor_Data_Entry!A:A,A9,Labor_Data_Entry!C:C,"Dutch - Sint Maarten",Labor_Data_Entry!O:O,"Yes") + SUMIFS(Labor_Data_Entry!G:G,Labor_Data_Entry!A:A,A9,Labor_Data_Entry!C:C,"Dutch - Sint Maarten",Labor_Data_Entry!O:O,"Yes") -> 574.87 | F9: =SUMIFS(Labor_Data_Entry!N:N,Labor_Data_Entry!A:A,A9,Labor_Data_Entry!C:C,"Dutch - Sint Maarten",Labor_Data_Entry!O:O,"Yes") -> 0 | G9: =IFERROR(F9/E9,0) -> 0 | H9: =B9+E9 -> 1742.29 | I9: =C9+F9 -> 0 | J9: =IFERROR(I9/H9,0) -> 0 | K9: Morris indemnity added cost (0h) on French
A10: 2026-02 | B10: =SUMIFS(Labor_Data_Entry!E:E,Labor_Data_Entry!A:A,A10,Labor_Data_Entry!C:C,"French - Saint Martin",Labor_Data_Entry!O:O,"Yes") + SUMIFS(Labor_Data_Entry!F:F,Labor_Data_Entry!A:A,A10,Labor_Data_Entry!C:C,"French - Saint Martin",Labor_Data_Entry!O:O,"Yes") + SUMIFS(Labor_Data_Entry!G:G,Labor_Data_Entry!A:A,A10,Labor_Data_Entry!C:C,"French - Saint Martin",Labor_Data_Entry!O:O,"Yes") -> 513.1 | C10: =SUMIFS(Labor_Data_Entry!N:N,Labor_Data_Entry!A:A,A10,Labor_Data_Entry!C:C,"French - Saint Martin",Labor_Data_Entry!O:O,"Yes") -> 0 | D10: =IFERROR(C10/B10,0) -> 0 | E10: =SUMIFS(Labor_Data_Entry!E:E,Labor_Data_Entry!A:A,A10,Labor_Data_Entry!C:C,"Dutch - Sint Maarten",Labor_Data_Entry!O:O,"Yes") + SUMIFS(Labor_Data_Entry!F:F,Labor_Data_Entry!A:A,A10,Labor_Data_Entry!C:C,"Dutch - Sint Maarten",Labor_Data_Entry!O:O,"Yes") + SUMIFS(Labor_Data_Entry!G:G,Labor_Data_Entry!A:A,A10,Labor_Data_Entry!C:C,"Dutch - Sint Maarten",Labor_Data_Entry!O:O,"Yes") -> 479.59 | F10: =SUMIFS(Labor_Data_Entry!N:N,Labor_Data_Entry!A:A,A10,Labor_Data_Entry!C:C,"Dutch - Sint Maarten",Labor_Data_Entry!O:O,"Yes") -> 0 | G10: =IFERROR(F10/E10,0) -> 0 | H10: =B10+E10 -> 992.69 | I10: =C10+F10 -> 0 | J10: =IFERROR(I10/H10,0) -> 0 | K10: Dutch cleaner after excluding management
A11: 2026-03 | B11: =SUMIFS(Labor_Data_Entry!E:E,Labor_Data_Entry!A:A,A11,Labor_Data_Entry!C:C,"French - Saint Martin",Labor_Data_Entry!O:O,"Yes") + SUMIFS(Labor_Data_Entry!F:F,Labor_Data_Entry!A:A,A11,Labor_Data_Entry!C:C,"French - Saint Martin",Labor_Data_Entry!O:O,"Yes") + SUMIFS(Labor_Data_Entry!G:G,Labor_Data_Entry!A:A,A11,Labor_Data_Entry!C:C,"French - Saint Martin",Labor_Data_Entry!O:O,"Yes") -> 514.81 | C11: =SUMIFS(Labor_Data_Entry!N:N,Labor_Data_Entry!A:A,A11,Labor_Data_Entry!C:C,"French - Saint Martin",Labor_Data_Entry!O:O,"Yes") -> 0 | D11: =IFERROR(C11/B11,0) -> 0 | E11: =SUMIFS(Labor_Data_Entry!E:E,Labor_Data_Entry!A:A,A11,Labor_Data_Entry!C:C,"Dutch - Sint Maarten",Labor_Data_Entry!O:O,"Yes") + SUMIFS(Labor_Data_Entry!F:F,Labor_Data_Entry!A:A,A11,Labor_Data_Entry!C:C,"Dutch - Sint Maarten",Labor_Data_Entry!O:O,"Yes") + SUMIFS(Labor_Data_Entry!G:G,Labor_Data_Entry!A:A,A11,Labor_Data_Entry!C:C,"Dutch - Sint Maarten",Labor_Data_Entry!O:O,"Yes") -> 352.55 | F11: =SUMIFS(Labor_Data_Entry!N:N,Labor_Data_Entry!A:A,A11,Labor_Data_Entry!C:C,"Dutch - Sint Maarten",Labor_Data_Entry!O:O,"Yes") -> 0 | G11: =IFERROR(F11/E11,0) -> 0 | H11: =B11+E11 -> 867.36 | I11: =C11+F11 -> 0 | J11: =IFERROR(I11/H11,0) -> 0 | K11: Dutch stable once management removed
A28: OVERTIME HOURS TREND (Production Staff Only)
A29: French OT Hours: | B29: =SUMIFS(Labor_Data_Entry!F:F,Labor_Data_Entry!C:C,"French - Saint Martin",Labor_Data_Entry!O:O,"Yes") + SUMIFS(Labor_Data_Entry!G:G,Labor_Data_Entry!C:C,"French - Saint Martin",Labor_Data_Entry!O:O,"Yes") -> 382.72
A30: Dutch OT Hours: | B30: =SUMIFS(Labor_Data_Entry!F:F,Labor_Data_Entry!C:C,"Dutch - Sint Maarten",Labor_Data_Entry!O:O,"Yes") + SUMIFS(Labor_Data_Entry!G:G,Labor_Data_Entry!C:C,"Dutch - Sint Maarten",Labor_Data_Entry!O:O,"Yes") -> 211.44
A31: Total OT Hours (All Production): | B31: =B29+B30 -> 594.16
A33: HOW TO USE THIS TAB GOING FORWARD
A34: • When you send new payslips, I will add the rows and mark Production_Only = Yes or No.
A35: • All trends and the Dashboard avg hourly will automatically exclude management.
A36: • The yellow cells on Dashboard for exchange rates still control the USD conversion.
A37: • This tab now gives you a clean, undistorted view of actual factory labor efficiency on both sides of the island.
